Workbook

Sheet Story log
A1: date | B1: slot | C1: ref | D1: frame | E1: version (auto/hand) | F1: sticker | G1: reach | H1: views | I1: taps forward | J1: taps back | K1: exits | L1: next story | M1: replies (count in DMs) | N1: sticker taps (votes/answers) | O1: shares | P1: profile visits | Q1: follows | R1: exit rate | S1: replies per 100 reached | T1: votes per 100 reached | U1: notes
A2: 2026-11-08 | B2: 21:00 | C2: S01 | D2: 1 | R2: =IF(G2>0,K2/G2,"") | S2: =IF(G2>0,M2/G2*100,"") | T2: =IF(G2>0,N2/G2*100,"")
A3: 2026-11-08 | B3: 21:00 | C3: S01 | D3: 2 | F3: Quiz sticker: A about half / B about a q | R3: =IF(G3>0,K3/G3,"") | S3: =IF(G3>0,M3/G3*100,"") | T3: =IF(G3>0,N3/G3*100,"")
A4: 2026-11-09 | B4: 09:00 | C4: S01 | D4: 3 | R4: =IF(G4>0,K4/G4,"") | S4: =IF(G4>0,M4/G4*100,"") | T4: =IF(G4>0,N4/G4*100,"")
A5: 2026-11-09 | B5: 09:00 | C5: S01 | D5: 4 | R5: =IF(G5>0,K5/G5,"") | S5: =IF(G5>0,M5/G5*100,"") | T5: =IF(G5>0,N5/G5*100,"")
A6: 2026-11-09 | B6: 21:00 | C6: C28 | D6: 1 | F6: Slider: 🧠 this month → 🗿 never | R6: =IF(G6>0,K6/G6,"") | S6: =IF(G6>0,M6/G6*100,"") | T6: =IF(G6>0,N6/G6*100,"")
A7: 2026-11-09 | B7: 21:00 | C7: C28 | D7: 2 | R7: =IF(G7>0,K7/G7,"") | S7: =IF(G7>0,M7/G7*100,"") | T7: =IF(G7>0,N7/G7*100,"")
A8: 2026-11-10 | B8: 09:00 | C8: C28 | D8: 3 | R8: =IF(G8>0,K8/G8,"") | S8: =IF(G8>0,M8/G8*100,"") | T8: =IF(G8>0,N8/G8*100,"")
A9: 2026-11-10 | B9: 09:00 | C9: C28 | D9: 4 | R9: =IF(G9>0,K9/G9,"") | S9: =IF(G9>0,M9/G9*100,"") | T9: =IF(G9>0,N9/G9*100,"")
A10: 2026-11-10 | B10: 21:00 | C10: S03 | D10: 1 | R10: =IF(G10>0,K10/G10,"") | S10: =IF(G10>0,M10/G10*100,"") | T10: =IF(G10>0,N10/G10*100,"")
A11: 2026-11-10 | B11: 21:00 | C11: S03 | D11: 2 | F11: Poll sticker: Look at the bird / Keep ty | R11: =IF(G11>0,K11/G11,"") | S11: =IF(G11>0,M11/G11*100,"") | T11: =IF(G11>0,N11/G11*100,"")
A12: 2026-11-11 | B12: 09:00 | C12: S03 | D12: 3 | R12: =IF(G12>0,K12/G12,"") | S12: =IF(G12>0,M12/G12*100,"") | T12: =IF(G12>0,N12/G12*100,"")
A13: 2026-11-11 | B13: 09:00 | C13: S03 | D13: 4 | R13: =IF(G13>0,K13/G13,"") | S13: =IF(G13>0,M13/G13*100,"") | T13: =IF(G13>0,N13/G13*100,"")
A14: 2026-11-11 | B14: 21:00 | C14: S07 | D14: 1 | R14: =IF(G14>0,K14/G14,"") | S14: =IF(G14>0,M14/G14*100,"") | T14: =IF(G14>0,N14/G14*100,"")
A15: 2026-11-11 | B15: 21:00 | C15: S07 | D15: 2 | F15: Quiz sticker: A wash their hands / B ope | R15: =IF(G15>0,K15/G15,"") | S15: =IF(G15>0,M15/G15*100,"") | T15: =IF(G15>0,N15/G15*100,"")
A16: 2026-11-12 | B16: 09:00 | C16: S07 | D16: 3 | R16: =IF(G16>0,K16/G16,"") | S16: =IF(G16>0,M16/G16*100,"") | T16: =IF(G16>0,N16/G16*100,"")
A17: 2026-11-12 | B17: 09:00 | C17: S07 | D17: 4 | F17: Question box | R17: =IF(G17>0,K17/G17,"") | S17: =IF(G17>0,M17/G17*100,"") | T17: =IF(G17>0,N17/G17*100,"")
A18: 2026-11-12 | B18: 21:00 | C18: S02 | D18: 1 | R18: =IF(G18>0,K18/G18,"") | S18: =IF(G18>0,M18/G18*100,"") | T18: =IF(G18>0,N18/G18*100,"")
A19: 2026-11-12 | B19: 21:00 | C19: S02 | D19: 2 | F19: Poll sticker: Up to me / Not up to me. | R19: =IF(G19>0,K19/G19,"") | S19: =IF(G19>0,M19/G19*100,"") | T19: =IF(G19>0,N19/G19*100,"")
A20: 2026-11-13 | B20: 09:00 | C20: S02 | D20: 3 | R20: =IF(G20>0,K20/G20,"") | S20: =IF(G20>0,M20/G20*100,"") | T20: =IF(G20>0,N20/G20*100,"")
A21: 2026-11-13 | B21: 09:00 | C21: S02 | D21: 4 | R21: =IF(G21>0,K21/G21,"") | S21: =IF(G21>0,M21/G21*100,"") | T21: =IF(G21>0,N21/G21*100,"")
A22: 2026-11-13 | B22: 09:00 | C22: S02 | D22: 5 | F22: Question box: 'The part that's up to me | R22: =IF(G22>0,K22/G22,"") | S22: =IF(G22>0,M22/G22*100,"") | T22: =IF(G22>0,N22/G22*100,"")
A23: 2026-11-13 | B23: 21:00 | C23: X03 | D23: 1 | F23: Poll: History / Mind / Kindness | R23: =IF(G23>0,K23/G23,"") | S23: =IF(G23>0,M23/G23*100,"") | T23: =IF(G23>0,N23/G23*100,"")
A24: 2026-11-13 | B24: 21:00 | C24: X03 | D24: 2 | R24: =IF(G24>0,K24/G24,"") | S24: =IF(G24>0,M24/G24*100,"") | T24: =IF(G24>0,N24/G24*100,"")
A25: 2026-11-14 | B25: 09:00 | C25: X03 | D25: 3 | R25: =IF(G25>0,K25/G25,"") | S25: =IF(G25>0,M25/G25*100,"") | T25: =IF(G25>0,N25/G25*100,"")
A26: 2026-11-14 | B26: 09:00 | C26: X03 | D26: 4 | R26: =IF(G26>0,K26/G26,"") | S26: =IF(G26>0,M26/G26*100,"") | T26: =IF(G26>0,N26/G26*100,"")
A27: 2026-11-14 | B27: 21:00 | C27: C40 | D27: 1 | F27: Quiz: A wake early / B some things are u | R27: =IF(G27>0,K27/G27,"") | S27: =IF(G27>0,M27/G27*100,"") | T27: =IF(G27>0,N27/G27*100,"")
A28: 2026-11-14 | B28: 21:00 | C28: C40 | D28: 2 | R28: =IF(G28>0,K28/G28,"") | S28: =IF(G28>0,M28/G28*100,"") | T28: =IF(G28>0,N28/G28*100,"")
A29: 2026-11-15 | B29: 09:00 | C29: C40 | D29: 3 | R29: =IF(G29>0,K29/G29,"") | S29: =IF(G29>0,M29/G29*100,"") | T29: =IF(G29>0,N29/G29*100,"")
A30: 2026-11-15 | B30: 09:00 | C30: C40 | D30: 4 | R30: =IF(G30>0,K30/G30,"") | S30: =IF(G30>0,M30/G30*100,"") | T30: =IF(G30>0,N30/G30*100,"")
A31: 2026-11-15 | B31: 21:00 | C31: S08 | D31: 1 | R31: =IF(G31>0,K31/G31,"") | S31: =IF(G31>0,M31/G31*100,"") | T31: =IF(G31>0,N31/G31*100,"")
A32: 2026-11-15 | B32: 21:00 | C32: S08 | D32: 2 | F32: Quiz sticker: A more selfies / B they go | R32: =IF(G32>0,K32/G32,"") | S32: =IF(G32>0,M32/G32*100,"") | T32: =IF(G32>0,N32/G32*100,"")
A33: 2026-11-16 | B33: 09:00 | C33: S08 | D33: 3 | R33: =IF(G33>0,K33/G33,"") | S33: =IF(G33>0,M33/G33*100,"") | T33: =IF(G33>0,N33/G33*100,"")
A34: 2026-11-16 | B34: 09:00 | C34: S08 | D34: 4 | F34: Emoji slider 🏢 → 🌌: 'How much awe this w | R34: =IF(G34>0,K34/G34,"") | S34: =IF(G34>0,M34/G34*100,"") | T34: =IF(G34>0,N34/G34*100,"")
A35: 2026-11-16 | B35: 09:00 | C35: S08 | D35: 5 | R35: =IF(G35>0,K35/G35,"") | S35: =IF(G35>0,M35/G35*100,"") | T35: =IF(G35>0,N35/G35*100,"")
A36: 2026-11-16 | B36: 21:00 | C36: S12 | D36: 1 | R36: =IF(G36>0,K36/G36,"") | S36: =IF(G36>0,M36/G36*100,"") | T36: =IF(G36>0,N36/G36*100,"")
A37: 2026-11-16 | B37: 21:00 | C37: S12 | D37: 2 | F37: Question box: 'What does your envy want? | R37: =IF(G37>0,K37/G37,"") | S37: =IF(G37>0,M37/G37*100,"") | T37: =IF(G37>0,N37/G37*100,"")
A38: 2026-11-17 | B38: 09:00 | C38: S12 | D38: 3 | R38: =IF(G38>0,K38/G38,"") | S38: =IF(G38>0,M38/G38*100,"") | T38: =IF(G38>0,N38/G38*100,"")
A39: 2026-11-17 | B39: 09:00 | C39: S12 | D39: 4 | F39: Poll sticker: Their life / One thing in | R39: =IF(G39>0,K39/G39,"") | S39: =IF(G39>0,M39/G39*100,"") | T39: =IF(G39>0,N39/G39*100,"")
A40: 2026-11-17 | B40: 21:00 | C40: S04 | D40: 1 | R40: =IF(G40>0,K40/G40,"") | S40: =IF(G40>0,M40/G40*100,"") | T40: =IF(G40>0,N40/G40*100,"")
...

Sheet Sequence summary
A1: ref | B1: first-frame reach | C1: last-frame reach | D1: completion | E1: total replies | F1: replies per 100 reached (first frame) | G1: total sticker taps | H1: shares | I1: follows | J1: follows per 1,000 reached | K1: verdict (keep / tweak / drop)
A2: S01 | B2: =IFERROR(INDEX('Story log'!G:G,MATCH("S01",'Story log'!C:C,0)),"") | C2: =IFERROR(LOOKUP(2,1/('Story log'!C2:C500="S01"),'Story log'!G2:G500),"") | D2: =IF(AND(ISNUMBER(B2),B2>0,ISNUMBER(C2)),C2/B2,"") | E2: =SUMIF('Story log'!C:C,"S01",'Story log'!M:M) | F2: =IF(AND(ISNUMBER(B2),B2>0),E2/B2*100,"") | G2: =SUMIF('Story log'!C:C,"S01",'Story log'!N:N) | H2: =SUMIF('Story log'!C:C,"S01",'Story log'!O:O) | I2: =SUMIF('Story log'!C:C,"S01",'Story log'!Q:Q) | J2: =IF(AND(ISNUMBER(B2),B2>0),I2/B2*1000,"")
A3: C28 | B3: =IFERROR(INDEX('Story log'!G:G,MATCH("C28",'Story log'!C:C,0)),"") | C3: =IFERROR(LOOKUP(2,1/('Story log'!C2:C500="C28"),'Story log'!G2:G500),"") | D3: =IF(AND(ISNUMBER(B3),B3>0,ISNUMBER(C3)),C3/B3,"") | E3: =SUMIF('Story log'!C:C,"C28",'Story log'!M:M) | F3: =IF(AND(ISNUMBER(B3),B3>0),E3/B3*100,"") | G3: =SUMIF('Story log'!C:C,"C28",'Story log'!N:N) | H3: =SUMIF('Story log'!C:C,"C28",'Story log'!O:O) | I3: =SUMIF('Story log'!C:C,"C28",'Story log'!Q:Q) | J3: =IF(AND(ISNUMBER(B3),B3>0),I3/B3*1000,"")
A4: S03 | B4: =IFERROR(INDEX('Story log'!G:G,MATCH("S03",'Story log'!C:C,0)),"") | C4: =IFERROR(LOOKUP(2,1/('Story log'!C2:C500="S03"),'Story log'!G2:G500),"") | D4: =IF(AND(ISNUMBER(B4),B4>0,ISNUMBER(C4)),C4/B4,"") | E4: =SUMIF('Story log'!C:C,"S03",'Story log'!M:M) | F4: =IF(AND(ISNUMBER(B4),B4>0),E4/B4*100,"") | G4: =SUMIF('Story log'!C:C,"S03",'Story log'!N:N) | H4: =SUMIF('Story log'!C:C,"S03",'Story log'!O:O) | I4: =SUMIF('Story log'!C:C,"S03",'Story log'!Q:Q) | J4: =IF(AND(ISNUMBER(B4),B4>0),I4/B4*1000,"")
A5: S07 | B5: =IFERROR(INDEX('Story log'!G:G,MATCH("S07",'Story log'!C:C,0)),"") | C5: =IFERROR(LOOKUP(2,1/('Story log'!C2:C500="S07"),'Story log'!G2:G500),"") | D5: =IF(AND(ISNUMBER(B5),B5>0,ISNUMBER(C5)),C5/B5,"") | E5: =SUMIF('Story log'!C:C,"S07",'Story log'!M:M) | F5: =IF(AND(ISNUMBER(B5),B5>0),E5/B5*100,"") | G5: =SUMIF('Story log'!C:C,"S07",'Story log'!N:N) | H5: =SUMIF('Story log'!C:C,"S07",'Story log'!O:O) | I5: =SUMIF('Story log'!C:C,"S07",'Story log'!Q:Q) | J5: =IF(AND(ISNUMBER(B5),B5>0),I5/B5*1000,"")
A6: S02 | B6: =IFERROR(INDEX('Story log'!G:G,MATCH("S02",'Story log'!C:C,0)),"") | C6: =IFERROR(LOOKUP(2,1/('Story log'!C2:C500="S02"),'Story log'!G2:G500),"") | D6: =IF(AND(ISNUMBER(B6),B6>0,ISNUMBER(C6)),C6/B6,"") | E6: =SUMIF('Story log'!C:C,"S02",'Story log'!M:M) | F6: =IF(AND(ISNUMBER(B6),B6>0),E6/B6*100,"") | G6: =SUMIF('Story log'!C:C,"S02",'Story log'!N:N) | H6: =SUMIF('Story log'!C:C,"S02",'Story log'!O:O) | I6: =SUMIF('Story log'!C:C,"S02",'Story log'!Q:Q) | J6: =IF(AND(ISNUMBER(B6),B6>0),I6/B6*1000,"")
A7: X03 | B7: =IFERROR(INDEX('Story log'!G:G,MATCH("X03",'Story log'!C:C,0)),"") | C7: =IFERROR(LOOKUP(2,1/('Story log'!C2:C500="X03"),'Story log'!G2:G500),"") | D7: =IF(AND(ISNUMBER(B7),B7>0,ISNUMBER(C7)),C7/B7,"") | E7: =SUMIF('Story log'!C:C,"X03",'Story log'!M:M) | F7: =IF(AND(ISNUMBER(B7),B7>0),E7/B7*100,"") | G7: =SUMIF('Story log'!C:C,"X03",'Story log'!N:N) | H7: =SUMIF('Story log'!C:C,"X03",'Story log'!O:O) | I7: =SUMIF('Story log'!C:C,"X03",'Story log'!Q:Q) | J7: =IF(AND(ISNUMBER(B7),B7>0),I7/B7*1000,"")
A8: C40 | B8: =IFERROR(INDEX('Story log'!G:G,MATCH("C40",'Story log'!C:C,0)),"") | C8: =IFERROR(LOOKUP(2,1/('Story log'!C2:C500="C40"),'Story log'!G2:G500),"") | D8: =IF(AND(ISNUMBER(B8),B8>0,ISNUMBER(C8)),C8/B8,"") | E8: =SUMIF('Story log'!C:C,"C40",'Story log'!M:M) | F8: =IF(AND(ISNUMBER(B8),B8>0),E8/B8*100,"") | G8: =SUMIF('Story log'!C:C,"C40",'Story log'!N:N) | H8: =SUMIF('Story log'!C:C,"C40",'Story log'!O:O) | I8: =SUMIF('Story log'!C:C,"C40",'Story log'!Q:Q) | J8: =IF(AND(ISNUMBER(B8),B8>0),I8/B8*1000,"")
A9: S08 | B9: =IFERROR(INDEX('Story log'!G:G,MATCH("S08",'Story log'!C:C,0)),"") | C9: =IFERROR(LOOKUP(2,1/('Story log'!C2:C500="S08"),'Story log'!G2:G500),"") | D9: =IF(AND(ISNUMBER(B9),B9>0,ISNUMBER(C9)),C9/B9,"") | E9: =SUMIF('Story log'!C:C,"S08",'Story log'!M:M) | F9: =IF(AND(ISNUMBER(B9),B9>0),E9/B9*100,"") | G9: =SUMIF('Story log'!C:C,"S08",'Story log'!N:N) | H9: =SUMIF('Story log'!C:C,"S08",'Story log'!O:O) | I9: =SUMIF('Story log'!C:C,"S08",'Story log'!Q:Q) | J9: =IF(AND(ISNUMBER(B9),B9>0),I9/B9*1000,"")
A10: S12 | B10: =IFERROR(INDEX('Story log'!G:G,MATCH("S12",'Story log'!C:C,0)),"") | C10: =IFERROR(LOOKUP(2,1/('Story log'!C2:C500="S12"),'Story log'!G2:G500),"") | D10: =IF(AND(ISNUMBER(B10),B10>0,ISNUMBER(C10)),C10/B10,"") | E10: =SUMIF('Story log'!C:C,"S12",'Story log'!M:M) | F10: =IF(AND(ISNUMBER(B10),B10>0),E10/B10*100,"") | G10: =SUMIF('Story log'!C:C,"S12",'Story log'!N:N) | H10: =SUMIF('Story log'!C:C,"S12",'Story log'!O:O) | I10: =SUMIF('Story log'!C:C,"S12",'Story log'!Q:Q) | J10: =IF(AND(ISNUMBER(B10),B10>0),I10/B10*1000,"")
A11: S04 | B11: =IFERROR(INDEX('Story log'!G:G,MATCH("S04",'Story log'!C:C,0)),"") | C11: =IFERROR(LOOKUP(2,1/('Story log'!C2:C500="S04"),'Story log'!G2:G500),"") | D11: =IF(AND(ISNUMBER(B11),B11>0,ISNUMBER(C11)),C11/B11,"") | E11: =SUMIF('Story log'!C:C,"S04",'Story log'!M:M) | F11: =IF(AND(ISNUMBER(B11),B11>0),E11/B11*100,"") | G11: =SUMIF('Story log'!C:C,"S04",'Story log'!N:N) | H11: =SUMIF('Story log'!C:C,"S04",'Story log'!O:O) | I11: =SUMIF('Story log'!C:C,"S04",'Story log'!Q:Q) | J11: =IF(AND(ISNUMBER(B11),B11>0),I11/B11*1000,"")
A12: C45 | B12: =IFERROR(INDEX('Story log'!G:G,MATCH("C45",'Story log'!C:C,0)),"") | C12: =IFERROR(LOOKUP(2,1/('Story log'!C2:C500="C45"),'Story log'!G2:G500),"") | D12: =IF(AND(ISNUMBER(B12),B12>0,ISNUMBER(C12)),C12/B12,"") | E12: =SUMIF('Story log'!C:C,"C45",'Story log'!M:M) | F12: =IF(AND(ISNUMBER(B12),B12>0),E12/B12*100,"") | G12: =SUMIF('Story log'!C:C,"C45",'Story log'!N:N) | H12: =SUMIF('Story log'!C:C,"C45",'Story log'!O:O) | I12: =SUMIF('Story log'!C:C,"C45",'Story log'!Q:Q) | J12: =IF(AND(ISNUMBER(B12),B12>0),I12/B12*1000,"")
A13: S10 | B13: =IFERROR(INDEX('Story log'!G:G,MATCH("S10",'Story log'!C:C,0)),"") | C13: =IFERROR(LOOKUP(2,1/('Story log'!C2:C500="S10"),'Story log'!G2:G500),"") | D13: =IF(AND(ISNUMBER(B13),B13>0,ISNUMBER(C13)),C13/B13,"") | E13: =SUMIF('Story log'!C:C,"S10",'Story log'!M:M) | F13: =IF(AND(ISNUMBER(B13),B13>0),E13/B13*100,"") | G13: =SUMIF('Story log'!C:C,"S10",'Story log'!N:N) | H13: =SUMIF('Story log'!C:C,"S10",'Story log'!O:O) | I13: =SUMIF('Story log'!C:C,"S10",'Story log'!Q:Q) | J13: =IF(AND(ISNUMBER(B13),B13>0),I13/B13*1000,"")
A14: X03 | B14: =IFERROR(INDEX('Story log'!G:G,MATCH("X03",'Story log'!C:C,0)),"") | C14: =IFERROR(LOOKUP(2,1/('Story log'!C2:C500="X03"),'Story log'!G2:G500),"") | D14: =IF(AND(ISNUMBER(B14),B14>0,ISNUMBER(C14)),C14/B14,"") | E14: =SUMIF('Story log'!C:C,"X03",'Story log'!M:M) | F14: =IF(AND(ISNUMBER(B14),B14>0),E14/B14*100,"") | G14: =SUMIF('Story log'!C:C,"X03",'Story log'!N:N) | H14: =SUMIF('Story log'!C:C,"X03",'Story log'!O:O) | I14: =SUMIF('Story log'!C:C,"X03",'Story log'!Q:Q) | J14: =IF(AND(ISNUMBER(B14),B14>0),I14/B14*1000,"")
A15: S06 | B15: =IFERROR(INDEX('Story log'!G:G,MATCH("S06",'Story log'!C:C,0)),"") | C15: =IFERROR(LOOKUP(2,1/('Story log'!C2:C500="S06"),'Story log'!G2:G500),"") | D15: =IF(AND(ISNUMBER(B15),B15>0,ISNUMBER(C15)),C15/B15,"") | E15: =SUMIF('Story log'!C:C,"S06",'Story log'!M:M) | F15: =IF(AND(ISNUMBER(B15),B15>0),E15/B15*100,"") | G15: =SUMIF('Story log'!C:C,"S06",'Story log'!N:N) | H15: =SUMIF('Story log'!C:C,"S06",'Story log'!O:O) | I15: =SUMIF('Story log'!C:C,"S06",'Story log'!Q:Q) | J15: =IF(AND(ISNUMBER(B15),B15>0),I15/B15*1000,"")
A16: S15 | B16: =IFERROR(INDEX('Story log'!G:G,MATCH("S15",'Story log'!C:C,0)),"") | C16: =IFERROR(LOOKUP(2,1/('Story log'!C2:C500="S15"),'Story log'!G2:G500),"") | D16: =IF(AND(ISNUMBER(B16),B16>0,ISNUMBER(C16)),C16/B16,"") | E16: =SUMIF('Story log'!C:C,"S15",'Story log'!M:M) | F16: =IF(AND(ISNUMBER(B16),B16>0),E16/B16*100,"") | G16: =SUMIF('Story log'!C:C,"S15",'Story log'!N:N) | H16: =SUMIF('Story log'!C:C,"S15",'Story log'!O:O) | I16: =SUMIF('Story log'!C:C,"S15",'Story log'!Q:Q) | J16: =IF(AND(ISNUMBER(B16),B16>0),I16/B16*1000,"")
A17: C35 | B17: =IFERROR(INDEX('Story log'!G:G,MATCH("C35",'Story log'!C:C,0)),"") | C17: =IFERROR(LOOKUP(2,1/('Story log'!C2:C500="C35"),'Story log'!G2:G500),"") | D17: =IF(AND(ISNUMBER(B17),B17>0,ISNUMBER(C17)),C17/B17,"") | E17: =SUMIF('Story log'!C:C,"C35",'Story log'!M:M) | F17: =IF(AND(ISNUMBER(B17),B17>0),E17/B17*100,"") | G17: =SUMIF('Story log'!C:C,"C35",'Story log'!N:N) | H17: =SUMIF('Story log'!C:C,"C35",'Story log'!O:O) | I17: =SUMIF('Story log'!C:C,"C35",'Story log'!Q:Q) | J17: =IF(AND(ISNUMBER(B17),B17>0),I17/B17*1000,"")
A18: S09 | B18: =IFERROR(INDEX('Story log'!G:G,MATCH("S09",'Story log'!C:C,0)),"") | C18: =IFERROR(LOOKUP(2,1/('Story log'!C2:C500="S09"),'Story log'!G2:G500),"") | D18: =IF(AND(ISNUMBER(B18),B18>0,ISNUMBER(C18)),C18/B18,"") | E18: =SUMIF('Story log'!C:C,"S09",'Story log'!M:M) | F18: =IF(AND(ISNUMBER(B18),B18>0),E18/B18*100,"") | G18: =SUMIF('Story log'!C:C,"S09",'Story log'!N:N) | H18: =SUMIF('Story log'!C:C,"S09",'Story log'!O:O) | I18: =SUMIF('Story log'!C:C,"S09",'Story log'!Q:Q) | J18: =IF(AND(ISNUMBER(B18),B18>0),I18/B18*1000,"")
A19: S14 | B19: =IFERROR(INDEX('Story log'!G:G,MATCH("S14",'Story log'!C:C,0)),"") | C19: =IFERROR(LOOKUP(2,1/('Story log'!C2:C500="S14"),'Story log'!G2:G500),"") | D19: =IF(AND(ISNUMBER(B19),B19>0,ISNUMBER(C19)),C19/B19,"") | E19: =SUMIF('Story log'!C:C,"S14",'Story log'!M:M) | F19: =IF(AND(ISNUMBER(B19),B19>0),E19/B19*100,"") | G19: =SUMIF('Story log'!C:C,"S14",'Story log'!N:N) | H19: =SUMIF('Story log'!C:C,"S14",'Story log'!O:O) | I19: =SUMIF('Story log'!C:C,"S14",'Story log'!Q:Q) | J19: =IF(AND(ISNUMBER(B19),B19>0),I19/B19*1000,"")
A20: C41 | B20: =IFERROR(INDEX('Story log'!G:G,MATCH("C41",'Story log'!C:C,0)),"") | C20: =IFERROR(LOOKUP(2,1/('Story log'!C2:C500="C41"),'Story log'!G2:G500),"") | D20: =IF(AND(ISNUMBER(B20),B20>0,ISNUMBER(C20)),C20/B20,"") | E20: =SUMIF('Story log'!C:C,"C41",'Story log'!M:M) | F20: =IF(AND(ISNUMBER(B20),B20>0),E20/B20*100,"") | G20: =SUMIF('Story log'!C:C,"C41",'Story log'!N:N) | H20: =SUMIF('Story log'!C:C,"C41",'Story log'!O:O) | I20: =SUMIF('Story log'!C:C,"C41",'Story log'!Q:Q) | J20: =IF(AND(ISNUMBER(B20),B20>0),I20/B20*1000,"")
A21: X03 | B21: =IFERROR(INDEX('Story log'!G:G,MATCH("X03",'Story log'!C:C,0)),"") | C21: =IFERROR(LOOKUP(2,1/('Story log'!C2:C500="X03"),'Story log'!G2:G500),"") | D21: =IF(AND(ISNUMBER(B21),B21>0,ISNUMBER(C21)),C21/B21,"") | E21: =SUMIF('Story log'!C:C,"X03",'Story log'!M:M) | F21: =IF(AND(ISNUMBER(B21),B21>0),E21/B21*100,"") | G21: =SUMIF('Story log'!C:C,"X03",'Story log'!N:N) | H21: =SUMIF('Story log'!C:C,"X03",'Story log'!O:O) | I21: =SUMIF('Story log'!C:C,"X03",'Story log'!Q:Q) | J21: =IF(AND(ISNUMBER(B21),B21>0),I21/B21*1000,"")
A22: S11 | B22: =IFERROR(INDEX('Story log'!G:G,MATCH("S11",'Story log'!C:C,0)),"") | C22: =IFERROR(LOOKUP(2,1/('Story log'!C2:C500="S11"),'Story log'!G2:G500),"") | D22: =IF(AND(ISNUMBER(B22),B22>0,ISNUMBER(C22)),C22/B22,"") | E22: =SUMIF('Story log'!C:C,"S11",'Story log'!M:M) | F22: =IF(AND(ISNUMBER(B22),B22>0),E22/B22*100,"") | G22: =SUMIF('Story log'!C:C,"S11",'Story log'!N:N) | H22: =SUMIF('Story log'!C:C,"S11",'Story log'!O:O) | I22: =SUMIF('Story log'!C:C,"S11",'Story log'!Q:Q) | J22: =IF(AND(ISNUMBER(B22),B22>0),I22/B22*1000,"")
A23: C20 | B23: =IFERROR(INDEX('Story log'!G:G,MATCH("C20",'Story log'!C:C,0)),"") | C23: =IFERROR(LOOKUP(2,1/('Story log'!C2:C500="C20"),'Story log'!G2:G500),"") | D23: =IF(AND(ISNUMBER(B23),B23>0,ISNUMBER(C23)),C23/B23,"") | E23: =SUMIF('Story log'!C:C,"C20",'Story log'!M:M) | F23: =IF(AND(ISNUMBER(B23),B23>0),E23/B23*100,"") | G23: =SUMIF('Story log'!C:C,"C20",'Story log'!N:N) | H23: =SUMIF('Story log'!C:C,"C20",'Story log'!O:O) | I23: =SUMIF('Story log'!C:C,"C20",'Story log'!Q:Q) | J23: =IF(AND(ISNUMBER(B23),B23>0),I23/B23*1000,"")
A24: S05 | B24: =IFERROR(INDEX('Story log'!G:G,MATCH("S05",'Story log'!C:C,0)),"") | C24: =IFERROR(LOOKUP(2,1/('Story log'!C2:C500="S05"),'Story log'!G2:G500),"") | D24: =IF(AND(ISNUMBER(B24),B24>0,ISNUMBER(C24)),C24/B24,"") | E24: =SUMIF('Story log'!C:C,"S05",'Story log'!M:M) | F24: =IF(AND(ISNUMBER(B24),B24>0),E24/B24*100,"") | G24: =SUMIF('Story log'!C:C,"S05",'Story log'!N:N) | H24: =SUMIF('Story log'!C:C,"S05",'Story log'!O:O) | I24: =SUMIF('Story log'!C:C,"S05",'Story log'!Q:Q) | J24: =IF(AND(ISNUMBER(B24),B24>0),I24/B24*1000,"")
A25: S13 | B25: =IFERROR(INDEX('Story log'!G:G,MATCH("S13",'Story log'!C:C,0)),"") | C25: =IFERROR(LOOKUP(2,1/('Story log'!C2:C500="S13"),'Story log'!G2:G500),"") | D25: =IF(AND(ISNUMBER(B25),B25>0,ISNUMBER(C25)),C25/B25,"") | E25: =SUMIF('Story log'!C:C,"S13",'Story log'!M:M) | F25: =IF(AND(ISNUMBER(B25),B25>0),E25/B25*100,"") | G25: =SUMIF('Story log'!C:C,"S13",'Story log'!N:N) | H25: =SUMIF('Story log'!C:C,"S13",'Story log'!O:O) | I25: =SUMIF('Story log'!C:C,"S13",'Story log'!Q:Q) | J25: =IF(AND(ISNUMBER(B25),B25>0),I25/B25*1000,"")
A26: C42 | B26: =IFERROR(INDEX('Story log'!G:G,MATCH("C42",'Story log'!C:C,0)),"") | C26: =IFERROR(LOOKUP(2,1/('Story log'!C2:C500="C42"),'Story log'!G2:G500),"") | D26: =IF(AND(ISNUMBER(B26),B26>0,ISNUMBER(C26)),C26/B26,"") | E26: =SUMIF('Story log'!C:C,"C42",'Story log'!M:M) | F26: =IF(AND(ISNUMBER(B26),B26>0),E26/B26*100,"") | G26: =SUMIF('Story log'!C:C,"C42",'Story log'!N:N) | H26: =SUMIF('Story log'!C:C,"C42",'Story log'!O:O) | I26: =SUMIF('Story log'!C:C,"C42",'Story log'!Q:Q) | J26: =IF(AND(ISNUMBER(B26),B26>0),I26/B26*1000,"")
A27: C19 | B27: =IFERROR(INDEX('Story log'!G:G,MATCH("C19",'Story log'!C:C,0)),"") | C27: =IFERROR(LOOKUP(2,1/('Story log'!C2:C500="C19"),'Story log'!G2:G500),"") | D27: =IF(AND(ISNUMBER(B27),B27>0,ISNUMBER(C27)),C27/B27,"") | E27: =SUMIF('Story log'!C:C,"C19",'Story log'!M:M) | F27: =IF(AND(ISNUMBER(B27),B27>0),E27/B27*100,"") | G27: =SUMIF('Story log'!C:C,"C19",'Story log'!N:N) | H27: =SUMIF('Story log'!C:C,"C19",'Story log'!O:O) | I27: =SUMIF('Story log'!C:C,"C19",'Story log'!Q:Q) | J27: =IF(AND(ISNUMBER(B27),B27>0),I27/B27*1000,"")
A28: X03 | B28: =IFERROR(INDEX('Story log'!G:G,MATCH("X03",'Story log'!C:C,0)),"") | C28: =IFERROR(LOOKUP(2,1/('Story log'!C2:C500="X03"),'Story log'!G2:G500),"") | D28: =IF(AND(ISNUMBER(B28),B28>0,ISNUMBER(C28)),C28/B28,"") | E28: =SUMIF('Story log'!C:C,"X03",'Story log'!M:M) | F28: =IF(AND(ISNUMBER(B28),B28>0),E28/B28*100,"") | G28: =SUMIF('Story log'!C:C,"X03",'Story log'!N:N) | H28: =SUMIF('Story log'!C:C,"X03",'Story log'!O:O) | I28: =SUMIF('Story log'!C:C,"X03",'Story log'!Q:Q) | J28: =IF(AND(ISNUMBER(B28),B28>0),I28/B28*1000,"")
A29: X02 | B29: =IFERROR(INDEX('Story log'!G:G,MATCH("X02",'Story log'!C:C,0)),"") | C29: =IFERROR(LOOKUP(2,1/('Story log'!C2:C500="X02"),'Story log'!G2:G500),"") | D29: =IF(AND(ISNUMBER(B29),B29>0,ISNUMBER(C29)),C29/B29,"") | E29: =SUMIF('Story log'!C:C,"X02",'Story log'!M:M) | F29: =IF(AND(ISNUMBER(B29),B29>0),E29/B29*100,"") | G29: =SUMIF('Story log'!C:C,"X02",'Story log'!N:N) | H29: =SUMIF('Story log'!C:C,"X02",'Story log'!O:O) | I29: =SUMIF('Story log'!C:C,"X02",'Story log'!Q:Q) | J29: =IF(AND(ISNUMBER(B29),B29>0),I29/B29*1000,"")
A30: C23 | B30: =IFERROR(INDEX('Story log'!G:G,MATCH("C23",'Story log'!C:C,0)),"") | C30: =IFERROR(LOOKUP(2,1/('Story log'!C2:C500="C23"),'Story log'!G2:G500),"") | D30: =IF(AND(ISNUMBER(B30),B30>0,ISNUMBER(C30)),C30/B30,"") | E30: =SUMIF('Story log'!C:C,"C23",'Story log'!M:M) | F30: =IF(AND(ISNUMBER(B30),B30>0),E30/B30*100,"") | G30: =SUMIF('Story log'!C:C,"C23",'Story log'!N:N) | H30: =SUMIF('Story log'!C:C,"C23",'Story log'!O:O) | I30: =SUMIF('Story log'!C:C,"C23",'Story log'!Q:Q) | J30: =IF(AND(ISNUMBER(B30),B30>0),I30/B30*1000,"")
A31: C37 | B31: =IFERROR(INDEX('Story log'!G:G,MATCH("C37",'Story log'!C:C,0)),"") | C31: =IFERROR(LOOKUP(2,1/('Story log'!C2:C500="C37"),'Story log'!G2:G500),"") | D31: =IF(AND(ISNUMBER(B31),B31>0,ISNUMBER(C31)),C31/B31,"") | E31: =SUMIF('Story log'!C:C,"C37",'Story log'!M:M) | F31: =IF(AND(ISNUMBER(B31),B31>0),E31/B31*100,"") | G31: =SUMIF('Story log'!C:C,"C37",'Story log'!N:N) | H31: =SUMIF('Story log'!C:C,"C37",'Story log'!O:O) | I31: =SUMIF('Story log'!C:C,"C37",'Story log'!Q:Q) | J31: =IF(AND(ISNUMBER(B31),B31>0),I31/B31*1000,"")

Sheet Weekly
A1: week starting | B1: followers (Sunday) | C1: new followers | D1: accounts reached (7 days) | E1: story reach, average per story | F1: replies (all stories) | G1: DM conversations started | H1: profile visits | I1: what worked | J1: what to change
A2: 2026-11-08
A3: 2026-11-15
A4: 2026-11-22
A5: 2026-11-29
A6: 2026-12-06

Sheet How to fill
A1: Where the numbers come from: Instagram app > your story (or Archive > Stories) > swipe up > Insights. Fill within 24 hours, or from the archive later.
A2: Replies: Instagram's API returns 0 for story replies from accounts in Europe, so count them in your DMs (or the 'Replies' line in the app).
A3: Sticker taps: the poll / quiz / slider / question results on the hand-posted version (swipe up on the story).
A4: Completion = reach of the last frame / reach of the first frame of the same sequence.
A5: Exit rate = exits / reach for that frame. A frame with a much higher exit rate than its neighbours is the weak one.
A6: Replies per 100 reached is the main score for stories (Instagram ranks stories partly on replies). Follows per 1,000 reached is the growth score.
A7: Small numbers: with under 100 viewers a story, one reply moves the rate a lot. Judge on 5+ stories per arm, never on one night.
A8: Instagram does not report story metrics below 5 for some fields; leave the cell empty, don't write 0.
